Workbook

Sheet Raw_Data
A1: Order_ID | B1: Month | C1: Month_No | D1: Date | E1: City | F1: Category | G1: Product | H1: Channel | I1: Units_Sold | J1: Unit_Price | K1: Revenue | L1: Discount_% | M1: Net_Revenue | N1: Delivery_Days | O1: Order_Status | P1: Payment_Mode | Q1: Return_Reason | R1: Target_Revenue
A2: ORD1001 | B2: Jan | C2: 1 | D2: 2024-01-03 | E2: Hyderabad | F2: Electronics | G2: Smartphone | H2: Website | I2: 4 | J2: 799 | K2: 3196 | L2: 0 | M2: 3196 | N2: 9 | O2: Delivered | P2: COD | R2: 2700
A3: ORD1002 | B3: Feb | C3: 2 | D3: 2024-02-28 | E3: Mumbai | F3: Clothing | G3: Jeans | H3: Marketplace | I3: 4 | J3: 24999 | K3: 99996 | L3: 20 | M3: 79996.8 | N3: 7 | O3: Delivered | P3: Net Banking | R3: 74700
A4: ORD1003 | B4: Mar | C4: 3 | D4: 2024-03-28 | E4: Kolkata | F4: Electronics | G4: Laptop | H4: Mobile App | I4: 5 | J4: 799 | K4: 3995 | L4: 5 | M4: 3795.25 | N4: 6 | O4: Delivered | P4: COD | R4: 3300
A5: ORD1004 | B5: Apr | C5: 4 | D5: 2024-04-10 | E5: Hyderabad | F5: Home & Kitchen | G5: LED Bulb | H5: Website | I5: 12 | J5: 4999 | K5: 59988 | L5: 20 | M5: 47990.4 | N5: 2 | O5: Pending | P5: COD | R5: 41900
A6: ORD1005 | B6: May | C6: 5 | D6: 2024-05-13 | E6: Chennai | F6: Books | G6: Textbook | H6: Marketplace | I6: 2 | J6: 299 | K6: 598 | L6: 5 | M6: 568.1 | N6: 5 | O6: Pending | P6: Credit Card | R6: 600
A7: ORD1006 | B7: Jun | C7: 6 | D7: 2024-06-18 | E7: Pune | F7: Home & Kitchen | G7: Iron | H7: Website | I7: 6 | J7: 1999 | K7: 11994 | L7: 5 | M7: 11394.3 | N7: 5 | O7: Returned | P7: UPI | Q7: Late Delivery | R7: 11900
A8: ORD1007 | B8: Jul | C8: 7 | D8: 2024-07-02 | E8: Ahmedabad | F8: Clothing | G8: Jeans | H8: Mobile App | I8: 5 | J8: 24999 | K8: 124995 | L8: 20 | M8: 99996 | N8: 4 | O8: Delivered | P8: UPI | R8: 91900
A9: ORD1008 | B9: Aug | C9: 8 | D9: 2024-08-21 | E9: Hyderabad | F9: Home & Kitchen | G9: Iron | H9: Website | I9: 4 | J9: 12999 | K9: 51996 | L9: 10 | M9: 46796.4 | N9: 4 | O9: Delivered | P9: COD | R9: 52200
A10: ORD1009 | B10: Sep | C10: 9 | D10: 2024-09-08 | E10: Hyderabad | F10: Sports | G10: Yoga Mat | H10: Website | I10: 4 | J10: 7999 | K10: 31996 | L10: 20 | M10: 25596.8 | N10: 5 | O10: Returned | P10: COD | Q10: Late Delivery | R10: 24800
A11: ORD1010 | B11: Oct | C11: 10 | D11: 2024-10-13 | E11: Ahmedabad | F11: Clothing | G11: Kurta | H11: Website | I11: 13 | J11: 299 | K11: 3887 | L11: 0 | M11: 3887 | N11: 3 | O11: Delivered | P11: COD | R11: 4000
A12: ORD1011 | B12: Nov | C12: 11 | D12: 2024-11-25 | E12: Ahmedabad | F12: Sports | G12: Cycling Gloves | H12: Marketplace | I12: 5 | J12: 7999 | K12: 39995 | L12: 0 | M12: 39995 | N12: 2 | O12: Delivered | P12: Net Banking | R12: 43000
A13: ORD1012 | B13: Dec | C13: 12 | D13: 2024-12-04 | E13: Hyderabad | F13: Home & Kitchen | G13: Mixer | H13: Mobile App | I13: 3 | J13: 4999 | K13: 14997 | L13: 0 | M13: 14997 | N13: 5 | O13: Pending | P13: Credit Card | R13: 15000
A14: ORD1013 | B14: Jan | C14: 1 | D14: 2024-01-01 | E14: Chennai | F14: Home & Kitchen | G14: LED Bulb | H14: Website | I14: 6 | J14: 799 | K14: 4794 | L14: 20 | M14: 3835.2 | N14: 9 | O14: Cancelled | P14: Net Banking | R14: 3600
A15: ORD1014 | B15: Feb | C15: 2 | D15: 2024-02-25 | E15: Hyderabad | F15: Electronics | G15: Earbuds | H15: Website | I15: 1 | J15: 999 | K15: 999 | L15: 20 | M15: 799.2 | N15: 2 | O15: Delivered | P15: COD | R15: 900
A16: ORD1015 | B16: Mar | C16: 3 | D16: 2024-03-07 | E16: Bangalore | F16: Books | G16: Self-Help | H16: Marketplace | I16: 8 | J16: 7999 | K16: 63992 | L16: 5 | M16: 60792.4 | N16: 5 | O16: Delivered | P16: Net Banking | R16: 59400
A17: ORD1016 | B17: Apr | C17: 4 | D17: 2024-04-08 | E17: Hyderabad | F17: Books | G17: Self-Help | H17: Mobile App | I17: 11 | J17: 24999 | K17: 274989 | L17: 10 | M17: 247490.1 | N17: 8 | O17: Cancelled | P17: COD | R17: 219400
A18: ORD1017 | B18: May | C18: 5 | D18: 2024-05-02 | E18: Mumbai | F18: Electronics | G18: Earbuds | H18: Marketplace | I18: 9 | J18: 999 | K18: 8991 | L18: 20 | M18: 7192.8 | N18: 4 | O18: Delivered | P18: UPI | R18: 6600
A19: ORD1018 | B19: Jun | C19: 6 | D19: 2024-06-08 | E19: Chennai | F19: Home & Kitchen | G19: Mixer | H19: Mobile App | I19: 11 | J19: 4999 | K19: 54989 | L19: 5 | M19: 52239.55 | N19: 9 | O19: Delivered | P19: Net Banking | R19: 53400
A20: ORD1019 | B20: Jul | C20: 7 | D20: 2024-07-02 | E20: Chennai | F20: Sports | G20: Football | H20: Website | I20: 2 | J20: 24999 | K20: 49998 | L20: 15 | M20: 42498.3 | N20: 6 | O20: Delivered | P20: COD | R20: 47100
A21: ORD1020 | B21: Aug | C21: 8 | D21: 2024-08-06 | E21: Kolkata | F21: Electronics | G21: Smartphone | H21: Marketplace | I21: 6 | J21: 499 | K21: 2994 | L21: 5 | M21: 2844.3 | N21: 4 | O21: Delivered | P21: COD | R21: 2500
A22: ORD1021 | B22: Sep | C22: 9 | D22: 2024-09-03 | E22: Chennai | F22: Home & Kitchen | G22: Iron | H22: Website | I22: 8 | J22: 7999 | K22: 63992 | L22: 0 | M22: 63992 | N22: 1 | O22: Delivered | P22: Net Banking | R22: 70400
... A34: ORD1033 | B34: Sep | C34: 9 | D34: 2024-09-26 | E34: Mumbai | F34: Clothing | G34: Kurta | H34: Mobile App | I34: 10 | J34: 7999 | K34: 79990 | L34: 5 | M34: 75990.5 | N34: 7 | O34: Delivered | P34: Debit Card | R34: 72900
A35: ORD1034 | B35: Oct | C35: 10 | D35: 2024-10-08 | E35: Chennai | F35: Electronics | G35: Earbuds | H35: Marketplace | I35: 4 | J35: 24999 | K35: 99996 | L35: 0 | M35: 99996 | N35: 6 | O35: Returned | P35: COD | Q35: Late Delivery | R35: 107500
A36: ORD1035 | B36: Nov | C36: 11 | D36: 2024-11-02 | E36: Kolkata | F36: Clothing | G36: Jeans | H36: Website | I36: 3 | J36: 1999 | K36: 5997 | L36: 15 | M36: 5097.45 | N36: 4 | O36: Delivered | P36: UPI | R36: 4900
A37: ORD1036 | B37: Dec | C37: 12 | D37: 2024-12-09 | E37: Chennai | F37: Sports | G37: Yoga Mat | H37: Mobile App | I37: 6 | J37: 1499 | K37: 8994 | L37: 5 | M37: 8544.3 | N37: 4 | O37: Delivered | P37: Credit Card | R37: 8300
A38: ORD1037 | B38: Jan | C38: 1 | D38: 2024-01-09 | E38: Pune | F38: Electronics | G38: Earbuds | H38: Marketplace | I38: 9 | J38: 2999 | K38: 26991 | L38: 20 | M38: 21592.8 | N38: 6 | O38: Pending | P38: UPI | R38: 24000
A39: ORD1038 | B39: Feb | C39: 2 | D39: 2024-02-17 | E39: Hyderabad | F39: Clothing | G39: Kurta | H39: Website | I39: 2 | J39: 12999 | K39: 25998 | L39: 15 | M39: 22098.3 | N39: 6 | O39: Returned | P39: Debit Card | Q39: Damaged | R39: 22800
A40: ORD1039 | B40: Mar | C40: 3 | D40: 2024-03-24 | E40: Chennai | F40: Electronics | G40: Smartwatch | H40: Mobile App | I40: 1 | J40: 2999 | K40: 2999 | L40: 0 | M40: 2999 | N40: 9 | O40: Pending | P40: Net Banking | R40: 3200
A41: ORD1040 | B41: Apr | C41: 4 | D41: 2024-04-10 | E41: Kolkata | F41: Clothing | G41: Saree | H41: Website | I41: 11 | J41: 1999 | K41: 21989 | L41: 20 | M41: 17591.2 | N41: 6 | O41: Delivered | P41: UPI | R41: 18800
A42: ORD1041 | B42: May | C42: 5 | D42: 2024-05-06 | E42: Kolkata | F42: Books | G42: Textbook | H42: Mobile App | I42: 7 | J42: 1499 | K42: 10493 | L42: 20 | M42: 8394.4 | N42: 3 | O42: Delivered | P42: COD | R42: 8800
A43: ORD1042 | B43: Jun | C43: 6 | D43: 2024-06-11 | E43: Hyderabad | F43: Books | G43: Biography | H43: Mobile App | I43: 9 | J43: 299 | K43: 2691 | L43: 10 | M43: 2421.9 | N43: 5 | O43: Delivered | P43: Net Banking | R43: 2500
A44: ORD1043 | B44: Jul | C44: 7 | D44: 2024-07-21 | E44: Ahmedabad | F44: Sports | G44: Football | H44: Marketplace | I44: 4 | J44: 7999 | K44: 31996 | L44: 15 | M44: 27196.6 | N44: 3 | O44: Delivered | P44: Debit Card | R44: 27300
A45: ORD1044 | B45: Aug | C45: 8 | D45: 2024-08-16 | E45: Delhi | F45: Books | G45: Textbook | H45: Website | I45: 11 | J45: 1499 | K45: 16489 | L45: 5 | M45: 15664.55 | N45: 4 | O45: Delivered | P45: UPI | R45: 14500
A46: ORD1045 | B46: Sep | C46: 9 | D46: 2024-09-05 | E46: Ahmedabad | F46: Books | G46: Fiction Novel | H46: Mobile App | I46: 15 | J46: 24999 | K46: 374985 | L46: 20 | M46: 299988 | N46: 4 | O46: Returned | P46: COD | Q46: Damaged | R46: 291000
A47: ORD1046 | B47: Oct | C47: 10 | D47: 2024-10-26 | E47: Kolkata | F47: Electronics | G47: Smartphone | H47: Website | I47: 3 | J47: 7999 | K47: 23997 | L47: 15 | M47: 20397.45 | N47: 1 | O47: Delivered | P47: UPI | R47: 20100
A48: ORD1047 | B48: Nov | C48: 11 | D48: 2024-11-16 | E48: Pune | F48: Sports | G48: Cycling Gloves | H48: Mobile App | I48: 10 | J48: 7999 | K48: 79990 | L48: 15 | M48: 67991.5 | N48: 9 | O48: Delivered | P48: Credit Card | R48: 73000
A49: ORD1048 | B49: Dec | C49: 12 | D49: 2024-12-08 | E49: Chennai | F49: Sports | G49: Badminton Racket | H49: Marketplace | I49: 5 | J49: 7999 | K49: 39995 | L49: 15 | M49: 33995.75 | N49: 4 | O49: Delivered | P49: UPI | R49: 36200
A50: ORD1049 | B50: Jan | C50: 1 | D50: 2024-01-03 | E50: Pune | F50: Home & Kitchen | G50: Water Purifier | H50: Marketplace | I50: 2 | J50: 799 | K50: 1598 | L50: 5 | M50: 1518.1 | N50: 4 | O50: Delivered | P50: Credit Card | R50: 1600
A51: ORD1050 | B51: Feb | C51: 2 | D51: 2024-02-19 | E51: Pune | F51: Sports | G51: Football | H51: Marketplace | I51: 8 | J51: 2999 | K51: 23992 | L51: 0 | M51: 23992 | N51: 4 | O51: Cancelled | P51: COD | R51: 26900
...

Sheet Monthly_Summary
A1: Month | B1: Month_No | C1: Total_Orders | D1: Total_Revenue | E1: Total_Net_Revenue | F1: Target_Revenue | G1: Achievement_% | H1: Returns | I1: Return_Rate_% | J1: MoM_Growth_%
A2: Jan | B2: 1 | C2: =COUNTIFS(Raw_Data!B:B,A2) -> 25 | D2: =SUMIF(Raw_Data!B:B,A2,Raw_Data!K:K) -> 816327 | E2: =SUMIF(Raw_Data!B:B,A2,Raw_Data!M:M) -> 708897.35 | F2: =SUMIF(Raw_Data!B:B,A2,Raw_Data!R:R) -> 722400 | G2: =IFERROR(E2/F2,0) -> 0.98130862 | H2: =COUNTIFS(Raw_Data!B:B,A2,Raw_Data!O:O,"Returned") -> 6 | I2: =IFERROR(H2/C2,0) -> 0.24 | J2: 0
A3: Feb | B3: 2 | C3: =COUNTIFS(Raw_Data!B:B,A3) -> 25 | D3: =SUMIF(Raw_Data!B:B,A3,Raw_Data!K:K) -> 1244097 | E3: =SUMIF(Raw_Data!B:B,A3,Raw_Data!M:M) -> 1118868.6 | F3: =SUMIF(Raw_Data!B:B,A3,Raw_Data!R:R) -> 1140500 | G3: =IFERROR(E3/F3,0) -> 0.98103345 | H3: =COUNTIFS(Raw_Data!B:B,A3,Raw_Data!O:O,"Returned") -> 6 | I3: =IFERROR(H3/C3,0) -> 0.24 | J3: =IFERROR((E3-E2)/E2,0) -> 0.57832252
A4: Mar | B4: 3 | C4: =COUNTIFS(Raw_Data!B:B,A4) -> 25 | D4: =SUMIF(Raw_Data!B:B,A4,Raw_Data!K:K) -> 1767444 | E4: =SUMIF(Raw_Data!B:B,A4,Raw_Data!M:M) -> 1520021.9 | F4: =SUMIF(Raw_Data!B:B,A4,Raw_Data!R:R) -> 1427500 | G4: =IFERROR(E4/F4,0) -> 1.064814 | H4: =COUNTIFS(Raw_Data!B:B,A4,Raw_Data!O:O,"Returned") -> 0 | I4: =IFERROR(H4/C4,0) -> 0 | J4: =IFERROR((E4-E3)/E3,0) -> 0.35853476
A5: Apr | B5: 4 | C5: =COUNTIFS(Raw_Data!B:B,A5) -> 25 | D5: =SUMIF(Raw_Data!B:B,A5,Raw_Data!K:K) -> 1743268 | E5: =SUMIF(Raw_Data!B:B,A5,Raw_Data!M:M) -> 1560955.1 | F5: =SUMIF(Raw_Data!B:B,A5,Raw_Data!R:R) -> 1443900 | G5: =IFERROR(E5/F5,0) -> 1.0810687 | H5: =COUNTIFS(Raw_Data!B:B,A5,Raw_Data!O:O,"Returned") -> 3 | I5: =IFERROR(H5/C5,0) -> 0.12 | J5: =IFERROR((E5-E4)/E4,0) -> 0.026929282
A6: May | B6: 5 | C6: =COUNTIFS(Raw_Data!B:B,A6) -> 25 | D6: =SUMIF(Raw_Data!B:B,A6,Raw_Data!K:K) -> 847915 | E6: =SUMIF(Raw_Data!B:B,A6,Raw_Data!M:M) -> 791762.4 | F6: =SUMIF(Raw_Data!B:B,A6,Raw_Data!R:R) -> 756900 | G6: =IFERROR(E6/F6,0) -> 1.0460595 | H6: =COUNTIFS(Raw_Data!B:B,A6,Raw_Data!O:O,"Returned") -> 5 | I6: =IFERROR(H6/C6,0) -> 0.2 | J6: =IFERROR((E6-E5)/E5,0) -> -0.49277053
A7: Jun | B7: 6 | C7: =COUNTIFS(Raw_Data!B:B,A7) -> 25 | D7: =SUMIF(Raw_Data!B:B,A7,Raw_Data!K:K) -> 1652751 | E7: =SUMIF(Raw_Data!B:B,A7,Raw_Data!M:M) -> 1577165.6 | F7: =SUMIF(Raw_Data!B:B,A7,Raw_Data!R:R) -> 1543100 | G7: =IFERROR(E7/F7,0) -> 1.0220761 | H7: =COUNTIFS(Raw_Data!B:B,A7,Raw_Data!O:O,"Returned") -> 4 | I7: =IFERROR(H7/C7,0) -> 0.16 | J7: =IFERROR((E7-E6)/E6,0) -> 0.9919683
A8: Jul | B8: 7 | C8: =COUNTIFS(Raw_Data!B:B,A8) -> 25 | D8: =SUMIF(Raw_Data!B:B,A8,Raw_Data!K:K) -> 897139 | E8: =SUMIF(Raw_Data!B:B,A8,Raw_Data!M:M) -> 809349.15 | F8: =SUMIF(Raw_Data!B:B,A8,Raw_Data!R:R) -> 756000 | G8: =IFERROR(E8/F8,0) -> 1.0705677 | H8: =COUNTIFS(Raw_Data!B:B,A8,Raw_Data!O:O,"Returned") -> 3 | I8: =IFERROR(H8/C8,0) -> 0.12 | J8: =IFERROR((E8-E7)/E7,0) -> -0.48683312
A9: Aug | B9: 8 | C9: =COUNTIFS(Raw_Data!B:B,A9) -> 25 | D9: =SUMIF(Raw_Data!B:B,A9,Raw_Data!K:K) -> 1730857 | E9: =SUMIF(Raw_Data!B:B,A9,Raw_Data!M:M) -> 1562267 | F9: =SUMIF(Raw_Data!B:B,A9,Raw_Data!R:R) -> 1544000 | G9: =IFERROR(E9/F9,0) -> 1.011831 | H9: =COUNTIFS(Raw_Data!B:B,A9,Raw_Data!O:O,"Returned") -> 1 | I9: =IFERROR(H9/C9,0) -> 0.04 | J9: =IFERROR((E9-E8)/E8,0) -> 0.9302757
A10: Sep | B10: 9 | C10: =COUNTIFS(Raw_Data!B:B,A10) -> 25 | D10: =SUMIF(Raw_Data!B:B,A10,Raw_Data!K:K) -> 1795283 | E10: =SUMIF(Raw_Data!B:B,A10,Raw_Data!M:M) -> 1567008.7 | F10: =SUMIF(Raw_Data!B:B,A10,Raw_Data!R:R) -> 1487400 | G10: =IFERROR(E10/F10,0) -> 1.053522 | H10: =COUNTIFS(Raw_Data!B:B,A10,Raw_Data!O:O,"Returned") -> 6 | I10: =IFERROR(H10/C10,0) -> 0.24 | J10: =IFERROR((E10-E9)/E9,0) -> 0.0030351086
A11: Oct | B11: 10 | C11: =COUNTIFS(Raw_Data!B:B,A11) -> 25 | D11: =SUMIF(Raw_Data!B:B,A11,Raw_Data!K:K) -> 1626889 | E11: =SUMIF(Raw_Data!B:B,A11,Raw_Data!M:M) -> 1504139.1 | F11: =SUMIF(Raw_Data!B:B,A11,Raw_Data!R:R) -> 1557900 | G11: =IFERROR(E11/F11,0) -> 0.9654914 | H11: =COUNTIFS(Raw_Data!B:B,A11,Raw_Data!O:O,"Returned") -> 3 | I11: =IFERROR(H11/C11,0) -> 0.12 | J11: =IFERROR((E11-E10)/E10,0) -> -0.040120774
A12: Nov | B12: 11 | C12: =COUNTIFS(Raw_Data!B:B,A12) -> 25 | D12: =SUMIF(Raw_Data!B:B,A12,Raw_Data!K:K) -> 1039392 | E12: =SUMIF(Raw_Data!B:B,A12,Raw_Data!M:M) -> 905156.05 | F12: =SUMIF(Raw_Data!B:B,A12,Raw_Data!R:R) -> 893400 | G12: =IFERROR(E12/F12,0) -> 1.0131588 | H12: =COUNTIFS(Raw_Data!B:B,A12,Raw_Data!O:O,"Returned") -> 1 | I12: =IFERROR(H12/C12,0) -> 0.04 | J12: =IFERROR((E12-E11)/E11,0) -> -0.39822316
A13: Dec | B13: 12 | C13: =COUNTIFS(Raw_Data!B:B,A13) -> 25 | D13: =SUMIF(Raw_Data!B:B,A13,Raw_Data!K:K) -> 920349 | E13: =SUMIF(Raw_Data!B:B,A13,Raw_Data!M:M) -> 857765.2 | F13: =SUMIF(Raw_Data!B:B,A13,Raw_Data!R:R) -> 825200 | G13: =IFERROR(E13/F13,0) -> 1.0394634 | H13: =COUNTIFS(Raw_Data!B:B,A13,Raw_Data!O:O,"Returned") -> 6 | I13: =IFERROR(H13/C13,0) -> 0.24 | J13: =IFERROR((E13-E12)/E12,0) -> -0.052356552

Sheet City_Analysis
A1: City | B1: Total_Orders | C1: Total_Revenue | D1: Net_Revenue | E1: Returns | F1: Return_Rate_% | G1: Avg_Order_Value | H1: Rank
A2: Mumbai | B2: =COUNTIF(Raw_Data!E:E,A2) -> 38 | C2: =SUMIF(Raw_Data!E:E,A2,Raw_Data!K:K) -> 3195035 | D2: =SUMIF(Raw_Data!E:E,A2,Raw_Data!M:M) -> 2883388.1 | E2: =COUNTIFS(Raw_Data!E:E,A2,Raw_Data!O:O,"Returned") -> 5 | F2: =IFERROR(E2/B2,0) -> 0.13157895 | G2: =IFERROR(C2/B2,0) -> 84079.868 | H2: =RANK(C2,$C$2:$C$9,0) -> 1
A3: Pune | B3: =COUNTIF(Raw_Data!E:E,A3) -> 36 | C3: =SUMIF(Raw_Data!E:E,A3,Raw_Data!K:K) -> 2421021 | D3: =SUMIF(Raw_Data!E:E,A3,Raw_Data!M:M) -> 2193023.6 | E3: =COUNTIFS(Raw_Data!E:E,A3,Raw_Data!O:O,"Returned") -> 7 | F3: =IFERROR(E3/B3,0) -> 0.19444444 | G3: =IFERROR(C3/B3,0) -> 67250.583 | H3: =RANK(C3,$C$2:$C$9,0) -> 2
A4: Ahmedabad | B4: =COUNTIF(Raw_Data!E:E,A4) -> 38 | C4: =SUMIF(Raw_Data!E:E,A4,Raw_Data!K:K) -> 2389891 | D4: =SUMIF(Raw_Data!E:E,A4,Raw_Data!M:M) -> 2086856.6 | E4: =COUNTIFS(Raw_Data!E:E,A4,Raw_Data!O:O,"Returned") -> 6 | F4: =IFERROR(E4/B4,0) -> 0.15789474 | G4: =IFERROR(C4/B4,0) -> 62891.868 | H4: =RANK(C4,$C$2:$C$9,0) -> 3
A5: Hyderabad | B5: =COUNTIF(Raw_Data!E:E,A5) -> 39 | C5: =SUMIF(Raw_Data!E:E,A5,Raw_Data!K:K) -> 2120015 | D5: =SUMIF(Raw_Data!E:E,A5,Raw_Data!M:M) -> 1918994.8 | E5: =COUNTIFS(Raw_Data!E:E,A5,Raw_Data!O:O,"Returned") -> 3 | F5: =IFERROR(E5/B5,0) -> 0.076923077 | G5: =IFERROR(C5/B5,0) -> 54359.359 | H5: =RANK(C5,$C$2:$C$9,0) -> 4
A6: Kolkata | B6: =COUNTIF(Raw_Data!E:E,A6) -> 45 | C6: =SUMIF(Raw_Data!E:E,A6,Raw_Data!K:K) -> 1742653 | D6: =SUMIF(Raw_Data!E:E,A6,Raw_Data!M:M) -> 1634166.9 | E6: =COUNTIFS(Raw_Data!E:E,A6,Raw_Data!O:O,"Returned") -> 7 | F6: =IFERROR(E6/B6,0) -> 0.15555556 | G6: =IFERROR(C6/B6,0) -> 38725.622 | H6: =RANK(C6,$C$2:$C$9,0) -> 5
A7: Chennai | B7: =COUNTIF(Raw_Data!E:E,A7) -> 41 | C7: =SUMIF(Raw_Data!E:E,A7,Raw_Data!K:K) -> 1626283 | D7: =SUMIF(Raw_Data!E:E,A7,Raw_Data!M:M) -> 1513882.9 | E7: =COUNTIFS(Raw_Data!E:E,A7,Raw_Data!O:O,"Returned") -> 7 | F7: =IFERROR(E7/B7,0) -> 0.17073171 | G7: =IFERROR(C7/B7,0) -> 39665.439 | H7: =RANK(C7,$C$2:$C$9,0) -> 7
A8: Delhi | B8: =COUNTIF(Raw_Data!E:E,A8) -> 30 | C8: =SUMIF(Raw_Data!E:E,A8,Raw_Data!K:K) -> 1707660 | D8: =SUMIF(Raw_Data!E:E,A8,Raw_Data!M:M) -> 1491462.4 | E8: =COUNTIFS(Raw_Data!E:E,A8,Raw_Data!O:O,"Returned") -> 5 | F8: =IFERROR(E8/B8,0) -> 0.16666667 | G8: =IFERROR(C8/B8,0) -> 56922 | H8: =RANK(C8,$C$2:$C$9,0) -> 6
A9: Bangalore | B9: =COUNTIF(Raw_Data!E:E,A9) -> 33 | C9: =SUMIF(Raw_Data!E:E,A9,Raw_Data!K:K) -> 879153 | D9: =SUMIF(Raw_Data!E:E,A9,Raw_Data!M:M) -> 761580.85 | E9: =COUNTIFS(Raw_Data!E:E,A9,Raw_Data!O:O,"Returned") -> 4 | F9: =IFERROR(E9/B9,0) -> 0.12121212 | G9: =IFERROR(C9/B9,0) -> 26641 | H9: =RANK(C9,$C$2:$C$9,0) -> 8

Sheet Category_Performance
A1: Category | B1: Total_Orders | C1: Revenue | D1: Net_Revenue | E1: Units_Sold | F1: Avg_Unit_Price | G1: Revenue_Share_% | H1: Return_Rate_% | I1: Best_Channel
A2: Electronics | B2: =COUNTIF(Raw_Data!F:F,A2) -> 56 | C2: =SUMIF(Raw_Data!F:F,A2,Raw_Data!K:K) -> 4036928 | D2: =SUMIF(Raw_Data!F:F,A2,Raw_Data!M:M) -> 3636484.4 | E2: =SUMIF(Raw_Data!F:F,A2,Raw_Data!I:I) -> 472 | F2: =IFERROR(C2/B2,0) -> 72088 | G2: =IFERROR(C2/SUM($C$2:$C$6),0) -> 0.25102603 | H2: =IFERROR(COUNTIFS(Raw_Data!F:F,A2,Raw_Data!O:O,"Returned")/B2,0) -> 0.16071429 | I2: =IFERROR(INDEX(Raw_Data!H:H,MATCH(_xludf.maxifs(Raw_Data!K:K,Raw_Data!F:F,A2),Raw_Data!K:K,0)),"N/A") -> N/A
A3: Home & Kitchen | B3: =COUNTIF(Raw_Data!F:F,A3) -> 68 | C3: =SUMIF(Raw_Data!F:F,A3,Raw_Data!K:K) -> 3512072 | D3: =SUMIF(Raw_Data!F:F,A3,Raw_Data!M:M) -> 3221897.6 | E3: =SUMIF(Raw_Data!F:F,A3,Raw_Data!I:I) -> 528 | F3: =IFERROR(C3/B3,0) -> 51648.118 | G3: =IFERROR(C3/SUM($C$2:$C$6),0) -> 0.2183892 | H3: =IFERROR(COUNTIFS(Raw_Data!F:F,A3,Raw_Data!O:O,"Returned")/B3,0) -> 0.14705882 | I3: =IFERROR(INDEX(Raw_Data!H:H,MATCH(_xludf.maxifs(Raw_Data!K:K,Raw_Data!F:F,A3),Raw_Data!K:K,0)),"N/A") -> N/A
A4: Books | B4: =COUNTIF(Raw_Data!F:F,A4) -> 55 | C4: =SUMIF(Raw_Data!F:F,A4,Raw_Data!K:K) -> 3338567 | D4: =SUMIF(Raw_Data!F:F,A4,Raw_Data!M:M) -> 2975591.2 | E4: =SUMIF(Raw_Data!F:F,A4,Raw_Data!I:I) -> 433 | F4: =IFERROR(C4/B4,0) -> 60701.218 | G4: =IFERROR(C4/SUM($C$2:$C$6),0) -> 0.20760024 | H4: =IFERROR(COUNTIFS(Raw_Data!F:F,A4,Raw_Data!O:O,"Returned")/B4,0) -> 0.12727273 | I4: =IFERROR(INDEX(Raw_Data!H:H,MATCH(_xludf.maxifs(Raw_Data!K:K,Raw_Data!F:F,A4),Raw_Data!K:K,0)),"N/A") -> N/A
A5: Clothing | B5: =COUNTIF(Raw_Data!F:F,A5) -> 59 | C5: =SUMIF(Raw_Data!F:F,A5,Raw_Data!K:K) -> 3022820 | D5: =SUMIF(Raw_Data!F:F,A5,Raw_Data!M:M) -> 2668666.7 | E5: =SUMIF(Raw_Data!F:F,A5,Raw_Data!I:I) -> 480 | F5: =IFERROR(C5/B5,0) -> 51234.237 | G5: =IFERROR(C5/SUM($C$2:$C$6),0) -> 0.18796632 | H5: =IFERROR(COUNTIFS(Raw_Data!F:F,A5,Raw_Data!O:O,"Returned")/B5,0) -> 0.10169492 | I5: =IFERROR(INDEX(Raw_Data!H:H,MATCH(_xludf.maxifs(Raw_Data!K:K,Raw_Data!F:F,A5),Raw_Data!K:K,0)),"N/A") -> N/A
A6: Sports | B6: =COUNTIF(Raw_Data!F:F,A6) -> 62 | C6: =SUMIF(Raw_Data!F:F,A6,Raw_Data!K:K) -> 2171324 | D6: =SUMIF(Raw_Data!F:F,A6,Raw_Data!M:M) -> 1980716.1 | E6: =SUMIF(Raw_Data!F:F,A6,Raw_Data!I:I) -> 476 | F6: =IFERROR(C6/B6,0) -> 35021.355 | G6: =IFERROR(C6/SUM($C$2:$C$6),0) -> 0.13501822 | H6: =IFERROR(COUNTIFS(Raw_Data!F:F,A6,Raw_Data!O:O,"Returned")/B6,0) -> 0.19354839 | I6: =IFERROR(INDEX(Raw_Data!H:H,MATCH(_xludf.maxifs(Raw_Data!K:K,Raw_Data!F:F,A6),Raw_Data!K:K,0)),"N/A") -> N/A

Sheet Channel_Analysis
A1: Channel | B1: Total_Orders | C1: Revenue | D1: Net_Revenue | E1: Returns | F1: Return_Rate_% | G1: Revenue_Share_% | H1: Avg_Discount_%
A2: Website | B2: =COUNTIF(Raw_Data!H:H,A2) -> 100 | C2: =SUMIF(Raw_Data!H:H,A2,Raw_Data!K:K) -> 5437745 | D2: =SUMIF(Raw_Data!H:H,A2,Raw_Data!M:M) -> 4959581.6 | E2: =COUNTIFS(Raw_Data!H:H,A2,Raw_Data!O:O,"Returned") -> 16 | F2: =IFERROR(E2/B2,0) -> 0.16 | G2: =IFERROR(C2/SUM($C$2:$C$4),0) -> 0.33813224 | H2: =IFERROR(AVERAGEIF(Raw_Data!H:H,A2,Raw_Data!L:L)/100,0) -> 0.101
A3: Mobile App | B3: =COUNTIF(Raw_Data!H:H,A3) -> 108 | C3: =SUMIF(Raw_Data!H:H,A3,Raw_Data!K:K) -> 5500474 | D3: =SUMIF(Raw_Data!H:H,A3,Raw_Data!M:M) -> 4801475.9 | E3: =COUNTIFS(Raw_Data!H:H,A3,Raw_Data!O:O,"Returned") -> 16 | F3: =IFERROR(E3/B3,0) -> 0.14814815 | G3: =IFERROR(C3/SUM($C$2:$C$4),0) -> 0.34203288 | H3: =IFERROR(AVERAGEIF(Raw_Data!H:H,A3,Raw_Data!L:L)/100,0) -> 0.10833333
A4: Marketplace | B4: =COUNTIF(Raw_Data!H:H,A4) -> 92 | C4: =SUMIF(Raw_Data!H:H,A4,Raw_Data!K:K) -> 5143492 | D4: =SUMIF(Raw_Data!H:H,A4,Raw_Data!M:M) -> 4722298.6 | E4: =COUNTIFS(Raw_Data!H:H,A4,Raw_Data!O:O,"Returned") -> 12 | F4: =IFERROR(E4/B4,0) -> 0.13043478 | G4: =IFERROR(C4/SUM($C$2:$C$4),0) -> 0.31983487 | H4: =IFERROR(AVERAGEIF(Raw_Data!H:H,A4,Raw_Data!L:L)/100,0) -> 0.094565217

Sheet Return_Analysis
A1: RETURN ANALYSIS — FY2024
A3: Return Reason | B3: Count | C3: % of Returns
A4: Quality Issue | B4: =COUNTIF(Raw_Data!Q:Q,A4) -> 7 | C4: =IFERROR(B4/SUM($B$4:$B$8),0) -> 0.17073171
A5: Wrong Item | B5: =COUNTIF(Raw_Data!Q:Q,A5) -> 9 | C5: =IFERROR(B5/SUM($B$4:$B$8),0) -> 0.2195122
A6: Changed Mind | B6: =COUNTIF(Raw_Data!Q:Q,A6) -> 6 | C6: =IFERROR(B6/SUM($B$4:$B$8),0) -> 0.14634146
A7: Damaged | B7: =COUNTIF(Raw_Data!Q:Q,A7) -> 11 | C7: =IFERROR(B7/SUM($B$4:$B$8),0) -> 0.26829268
A8: Late Delivery | B8: =COUNTIF(Raw_Data!Q:Q,A8) -> 8 | C8: =IFERROR(B8/SUM($B$4:$B$8),0) -> 0.19512195
A11: Category | B11: Returns | C11: Return Rate %
A12: Electronics | B12: =COUNTIFS(Raw_Data!F:F,A12,Raw_Data!O:O,"Returned") -> 9 | C12: =IFERROR(B12/COUNTIF(Raw_Data!F:F,A12),0) -> 0.16071429
A13: Clothing | B13: =COUNTIFS(Raw_Data!F:F,A13,Raw_Data!O:O,"Returned") -> 6 | C13: =IFERROR(B13/COUNTIF(Raw_Data!F:F,A13),0) -> 0.10169492
A14: Home & Kitchen | B14: =COUNTIFS(Raw_Data!F:F,A14,Raw_Data!O:O,"Returned") -> 10 | C14: =IFERROR(B14/COUNTIF(Raw_Data!F:F,A14),0) -> 0.14705882
A15: Sports | B15: =COUNTIFS(Raw_Data!F:F,A15,Raw_Data!O:O,"Returned") -> 12 | C15: =IFERROR(B15/COUNTIF(Raw_Data!F:F,A15),0) -> 0.19354839
A16: Books | B16: =COUNTIFS(Raw_Data!F:F,A16,Raw_Data!O:O,"Returned") -> 7 | C16: =IFERROR(B16/COUNTIF(Raw_Data!F:F,A16),0) -> 0.12727273

Sheet MIS_Dashboard
A1: 🛒 E-COMMERCE ORDER & RETURNS DASHBOARD — FY2024
B3: Total Orders | C3: Total Revenue | E3: Net Revenue | F3: Return Rate % | H3: Avg Order Value | I3: Target Achv %
B4: =COUNTA(Raw_Data!A:A)-1 -> 300 | C4: =SUM(Raw_Data!K:K) -> 16081711 | E4: =SUM(Raw_Data!M:M) -> 14483356 | F4: =COUNTIF(Raw_Data!O:O,"Returned")/(COUNTA(Raw_Data!A:A)-1) -> 0.14666667 | H4: =SUM(Raw_Data!M:M)/(COUNTA(Raw_Data!A:A)-1) -> 48277.854 | I4: =SUM(Raw_Data!M:M)/SUM(Raw_Data!R:R) -> 1.0273195
A7: Monthly Performance Summary
A8: Month | B8: Orders | C8: Revenue | D8: Net Revenue | E8: Target | F8: Achievement % | G8: Returns | H8: Return Rate | I8: MoM Growth
A9: Jan | B9: =COUNTIF(Raw_Data!B:B,A9) -> 25 | C9: =SUMIF(Raw_Data!B:B,A9,Raw_Data!K:K) -> 816327 | D9: =SUMIF(Raw_Data!B:B,A9,Raw_Data!M:M) -> 708897.35 | E9: =SUMIF(Raw_Data!B:B,A9,Raw_Data!R:R) -> 722400 | F9: =IFERROR(D9/E9,0) -> 0.98130862 | G9: =COUNTIFS(Raw_Data!B:B,A9,Raw_Data!O:O,"Returned") -> 6 | H9: =IFERROR(G9/B9,0) -> 0.24 | I9: 0
A10: Feb | B10: =COUNTIF(Raw_Data!B:B,A10) -> 25 | C10: =SUMIF(Raw_Data!B:B,A10,Raw_Data!K:K) -> 1244097 | D10: =SUMIF(Raw_Data!B:B,A10,Raw_Data!M:M) -> 1118868.6 | E10: =SUMIF(Raw_Data!B:B,A10,Raw_Data!R:R) -> 1140500 | F10: =IFERROR(D10/E10,0) -> 0.98103345 | G10: =COUNTIFS(Raw_Data!B:B,A10,Raw_Data!O:O,"Returned") -> 6 | H10: =IFERROR(G10/B10,0) -> 0.24 | I10: =IFERROR((D10-D9)/D9,0) -> 0.57832252
A11: Mar | B11: =COUNTIF(Raw_Data!B:B,A11) -> 25 | C11: =SUMIF(Raw_Data!B:B,A11,Raw_Data!K:K) -> 1767444 | D11: =SUMIF(Raw_Data!B:B,A11,Raw_Data!M:M) -> 1520021.9 | E11: =SUMIF(Raw_Data!B:B,A11,Raw_Data!R:R) -> 1427500 | F11: =IFERROR(D11/E11,0) -> 1.064814 | G11: =COUNTIFS(Raw_Data!B:B,A11,Raw_Data!O:O,"Returned") -> 0 | H11: =IFERROR(G11/B11,0) -> 0 | I11: =IFERROR((D11-D10)/D10,0) -> 0.35853476
A12: Apr | B12: =COUNTIF(Raw_Data!B:B,A12) -> 25 | C12: =SUMIF(Raw_Data!B:B,A12,Raw_Data!K:K) -> 1743268 | D12: =SUMIF(Raw_Data!B:B,A12,Raw_Data!M:M) -> 1560955.1 | E12: =SUMIF(Raw_Data!B:B,A12,Raw_Data!R:R) -> 1443900 | F12: =IFERROR(D12/E12,0) -> 1.0810687 | G12: =COUNTIFS(Raw_Data!B:B,A12,Raw_Data!O:O,"Returned") -> 3 | H12: =IFERROR(G12/B12,0) -> 0.12 | I12: =IFERROR((D12-D11)/D11,0) -> 0.026929282
A13: May | B13: =COUNTIF(Raw_Data!B:B,A13) -> 25 | C13: =SUMIF(Raw_Data!B:B,A13,Raw_Data!K:K) -> 847915 | D13: =SUMIF(Raw_Data!B:B,A13,Raw_Data!M:M) -> 791762.4 | E13: =SUMIF(Raw_Data!B:B,A13,Raw_Data!R:R) -> 756900 | F13: =IFERROR(D13/E13,0) -> 1.0460595 | G13: =COUNTIFS(Raw_Data!B:B,A13,Raw_Data!O:O,"Returned") -> 5 | H13: =IFERROR(G13/B13,0) -> 0.2 | I13: =IFERROR((D13-D12)/D12,0) -> -0.49277053
A14: Jun | B14: =COUNTIF(Raw_Data!B:B,A14) -> 25 | C14: =SUMIF(Raw_Data!B:B,A14,Raw_Data!K:K) -> 1652751 | D14: =SUMIF(Raw_Data!B:B,A14,Raw_Data!M:M) -> 1577165.6 | E14: =SUMIF(Raw_Data!B:B,A14,Raw_Data!R:R) -> 1543100 | F14: =IFERROR(D14/E14,0) -> 1.0220761 | G14: =COUNTIFS(Raw_Data!B:B,A14,Raw_Data!O:O,"Returned") -> 4 | H14: =IFERROR(G14/B14,0) -> 0.16 | I14: =IFERROR((D14-D13)/D13,0) -> 0.9919683
A15: Jul | B15: =COUNTIF(Raw_Data!B:B,A15) -> 25 | C15: =SUMIF(Raw_Data!B:B,A15,Raw_Data!K:K) -> 897139 | D15: =SUMIF(Raw_Data!B:B,A15,Raw_Data!M:M) -> 809349.15 | E15: =SUMIF(Raw_Data!B:B,A15,Raw_Data!R:R) -> 756000 | F15: =IFERROR(D15/E15,0) -> 1.0705677 | G15: =COUNTIFS(Raw_Data!B:B,A15,Raw_Data!O:O,"Returned") -> 3 | H15: =IFERROR(G15/B15,0) -> 0.12 | I15: =IFERROR((D15-D14)/D14,0) -> -0.48683312
A16: Aug | B16: =COUNTIF(Raw_Data!B:B,A16) -> 25 | C16: =SUMIF(Raw_Data!B:B,A16,Raw_Data!K:K) -> 1730857 | D16: =SUMIF(Raw_Data!B:B,A16,Raw_Data!M:M) -> 1562267 | E16: =SUMIF(Raw_Data!B:B,A16,Raw_Data!R:R) -> 1544000 | F16: =IFERROR(D16/E16,0) -> 1.011831 | G16: =COUNTIFS(Raw_Data!B:B,A16,Raw_Data!O:O,"Returned") -> 1 | H16: =IFERROR(G16/B16,0) -> 0.04 | I16: =IFERROR((D16-D15)/D15,0) -> 0.9302757
A17: Sep | B17: =COUNTIF(Raw_Data!B:B,A17) -> 25 | C17: =SUMIF(Raw_Data!B:B,A17,Raw_Data!K:K) -> 1795283 | D17: =SUMIF(Raw_Data!B:B,A17,Raw_Data!M:M) -> 1567008.7 | E17: =SUMIF(Raw_Data!B:B,A17,Raw_Data!R:R) -> 1487400 | F17: =IFERROR(D17/E17,0) -> 1.053522 | G17: =COUNTIFS(Raw_Data!B:B,A17,Raw_Data!O:O,"Returned") -> 6 | H17: =IFERROR(G17/B17,0) -> 0.24 | I17: =IFERROR((D17-D16)/D16,0) -> 0.0030351086
A18: Oct | B18: =COUNTIF(Raw_Data!B:B,A18) -> 25 | C18: =SUMIF(Raw_Data!B:B,A18,Raw_Data!K:K) -> 1626889 | D18: =SUMIF(Raw_Data!B:B,A18,Raw_Data!M:M) -> 1504139.1 | E18: =SUMIF(Raw_Data!B:B,A18,Raw_Data!R:R) -> 1557900 | F18: =IFERROR(D18/E18,0) -> 0.9654914 | G18: =COUNTIFS(Raw_Data!B:B,A18,Raw_Data!O:O,"Returned") -> 3 | H18: =IFERROR(G18/B18,0) -> 0.12 | I18: =IFERROR((D18-D17)/D17,0) -> -0.040120774
A19: Nov | B19: =COUNTIF(Raw_Data!B:B,A19) -> 25 | C19: =SUMIF(Raw_Data!B:B,A19,Raw_Data!K:K) -> 1039392 | D19: =SUMIF(Raw_Data!B:B,A19,Raw_Data!M:M) -> 905156.05 | E19: =SUMIF(Raw_Data!B:B,A19,Raw_Data!R:R) -> 893400 | F19: =IFERROR(D19/E19,0) -> 1.0131588 | G19: =COUNTIFS(Raw_Data!B:B,A19,Raw_Data!O:O,"Returned") -> 1 | H19: =IFERROR(G19/B19,0) -> 0.04 | I19: =IFERROR((D19-D18)/D18,0) -> -0.39822316
A20: Dec | B20: =COUNTIF(Raw_Data!B:B,A20) -> 25 | C20: =SUMIF(Raw_Data!B:B,A20,Raw_Data!K:K) -> 920349 | D20: =SUMIF(Raw_Data!B:B,A20,Raw_Data!M:M) -> 857765.2 | E20: =SUMIF(Raw_Data!B:B,A20,Raw_Data!R:R) -> 825200 | F20: =IFERROR(D20/E20,0) -> 1.0394634 | G20: =COUNTIFS(Raw_Data!B:B,A20,Raw_Data!O:O,"Returned") -> 6 | H20: =IFERROR(G20/B20,0) -> 0.24 | I20: =IFERROR((D20-D19)/D19,0) -> -0.052356552
